<?xml version="1.0" ?>

<robot name="robotis_pro7a" xmlns:xacro="http://www.ros.org/wiki/xacro">

  <!-- ros_control plugin -->
  <gazebo>
    <plugin name="gazebo_ros_control" filename="libgazebo_ros_control.so">
      <robotNamespace>/robotis_pro7a</robotNamespace>
      <robotSimType>gazebo_ros_control/DefaultRobotHWSim</robotSimType>
    </plugin>
  </gazebo>

  <!-- World -->
  <gazebo reference="world" />

  <!-- Link1 -->
  <gazebo reference="link1">
    <mu1>0.2</mu1>
    <mu2>0.2</mu2>
    <material>Gazebo/Grey</material>
  </gazebo>

  <!-- Link2 -->
  <gazebo reference="link2">
    <mu1>0.2</mu1>
    <mu2>0.2</mu2>
    <material>Gazebo/Grey</material>
  </gazebo>

  <!-- Link3 -->
  <gazebo reference="link3">
    <mu1>0.2</mu1>
    <mu2>0.2</mu2>
    <material>Gazebo/Grey</material>
  </gazebo>

  <!-- Link4 -->
  <gazebo reference="link4">
    <mu1>0.2</mu1>
    <mu2>0.2</mu2>
    <material>Gazebo/Grey</material>
  </gazebo>

  <!-- Link5 -->
  <gazebo reference="link5">
    <mu1>0.2</mu1>
    <mu2>0.2</mu2>
    <material>Gazebo/Grey</material>
  </gazebo>

  <!-- Link6 -->
  <gazebo reference="link6">
    <mu1>0.2</mu1>
    <mu2>0.2</mu2>
    <material>Gazebo/Grey</material>
  </gazebo>

  <!-- Link7 -->
  <gazebo reference="link7">
    <mu1>0.2</mu1>
    <mu2>0.2</mu2>
    <material>Gazebo/Grey</material>
  </gazebo>

  <!-- End_Link -->
  <gazebo reference="end_link">
    <mu1>0.2</mu1>
    <mu2>0.2</mu2>
    <material>Gazebo/Grey</material>
  </gazebo>

  <!-- world -->
  <link name="world" />

  <joint name="world_fixed" type="fixed">
    <origin xyz="0 0 0" rpy="0 0 0"/>
    <parent link="world"/>
    <child link="link1"/>
  </joint>
  
  <!-- link 1 -->
  <link name="link1">
    <inertial>
      <origin xyz="0 0 0" rpy="0 0 0" />
      <mass value="0.3236" />
      <inertia ixx="0.002" ixy="0.0" ixz="0.0" iyy="0.002" iyz="0.0" izz="0.002"/>
    </inertial>
    <visual>
      <origin xyz="0 0 0" rpy="0 0 0" />
      <geometry>
        <mesh filename="package://pro7a_description/meshes/link1.STL" />
      </geometry>
      <material name="">
        <color rgba="0.79216 0.81961 0.93333 1" />
      </material>
    </visual>
    <collision>
      <origin xyz="0 0 0" rpy="0 0 0" />
      <geometry>
        <mesh filename="package://pro7a_description/meshes/link1.STL" />
      </geometry>
    </collision>
  </link>

  <!-- joint 1 -->
  <joint name="joint1" type="revolute">
    <origin xyz="0 0 0.126" rpy="0 0 0" />
    <parent link="link1" />
    <child link="link2" />
    <axis xyz="0 0 1" />
    <limit effort="1000" lower="-2.62" upper="2.62" velocity="6.5"/>
    <dynamics damping="0.7"/>
  </joint>

  <transmission name="tran1">
    <type>transmission_interface/SimpleTransmission</type>
    <joint name="joint1">
      <hardwareInterface>EffortJointInterface</hardwareInterface>
    </joint>
    <actuator name="motor1">
      <hardwareInterface>EffortJointInterface</hardwareInterface>
      <mechanicalReduction>1</mechanicalReduction>
    </actuator>
  </transmission>

  <!-- link 2 -->
  <link name="link2">
    <inertial>
      <origin xyz="0 0.0014958 0.032763" rpy="0 0 0" />
      <mass value="0.35395" />
      <inertia ixx="0.002" ixy="0.0" ixz="0.0" iyy="0.002" iyz="0.0" izz="0.002"/>
    </inertial>
    <visual>
      <origin xyz="0 0 0" rpy="0 0 0" />
      <geometry>
        <mesh filename="package://pro7a_description/meshes/link2.STL" />
      </geometry>
      <material name="">
        <color rgba="0.79216 0.81961 0.93333 1" />
      </material>
    </visual>
    <collision>
      <origin xyz="0 0 0" rpy="0 0 0" />
      <geometry>
        <mesh filename="package://pro7a_description/meshes/link2.STL" />
      </geometry>
    </collision>
  </link>

  <!-- joint 2 -->
  <joint name="joint2" type="revolute">
    <origin xyz="0 -0.072 0.034" rpy="0 0 0" />
    <parent link="link2" />
    <child link="link3" />
    <axis xyz="0 1 0" />
    <limit effort="1000" lower="-1.570796327" upper="1.570796327" velocity="6.5"/>
    <dynamics damping="0.7"/>
  </joint>

  <transmission name="tran2">
    <type>transmission_interface/SimpleTransmission</type>
    <joint name="joint2">
      <hardwareInterface>EffortJointInterface</hardwareInterface>
    </joint>
    <actuator name="motor2">
      <hardwareInterface>EffortJointInterface</hardwareInterface>
      <mechanicalReduction>1</mechanicalReduction>
    </actuator>
  </transmission>

  <!-- link 3 -->
  <link name="link3">
    <inertial>
      <origin xyz="0.00014574 0.072437 0.12161" rpy="0 0 0" />
      <mass value="0.50149" />
      <inertia ixx="0.002" ixy="0.0" ixz="0.0" iyy="0.002" iyz="0.0" izz="0.002"/>
    </inertial>
    <visual>
      <origin xyz="0 0 0" rpy="0 0 0" />
      <geometry>
        <mesh filename="package://pro7a_description/meshes/link3.STL" />
      </geometry>
      <material name="">
        <color rgba="0.79216 0.81961 0.93333 1" />
      </material>
    </visual>
    <collision>
      <origin xyz="0 0 0" rpy="0 0 0" />
      <geometry>
        <mesh filename="package://pro7a_description/meshes/link3.STL" />
      </geometry>
    </collision>
  </link>

  <!-- joint 3 -->
  <joint name="joint3" type="revolute">
    <origin xyz="0 0.072 0.195" rpy="0 0 0" />
    <parent link="link3" />
    <child link="link4" />
    <axis xyz="0 0 1" />
    <limit effort="1000" lower="-2.62" upper="2.62" velocity="6.5"/>
    <dynamics damping="0.7" />
  </joint>

 <transmission name="tran3">
    <type>transmission_interface/SimpleTransmission</type>
    <joint name="joint3">
      <hardwareInterface>EffortJointInterface</hardwareInterface>
    </joint>
    <actuator name="motor3">
      <hardwareInterface>EffortJointInterface</hardwareInterface>
      <mechanicalReduction>1</mechanicalReduction>
    </actuator>
  </transmission>

  <!-- link 4 -->
  <link name="link4">
    <inertial>
      <origin xyz="0.015802 0 0.064569" rpy="0 0 0" />
      <mass value="0.53361" />
      <inertia ixx="0.002" ixy="0.0" ixz="0.0" iyy="0.002" iyz="0.0" izz="0.002"/>
    </inertial>
    <visual>
      <origin xyz="0 0 0" rpy="0 0 0" />
      <geometry>
        <mesh filename="package://pro7a_description/meshes/link4.STL" />
      </geometry>
      <material name="">
        <color rgba="0.89412 0.91373 0.92941 1" />
      </material>
    </visual>
    <collision>
      <origin xyz="0 0 0" rpy="0 0 0" />
      <geometry>
        <mesh filename="package://pro7a_description/meshes/link4.STL" />
      </geometry>
    </collision>
  </link>

  <!-- joint 4 -->
  <joint name="joint4" type="revolute">
    <origin xyz="0.03 -0.06 0.095" rpy="0 0 0" />
    <parent link="link4" />
    <child link="link5" />
    <axis xyz="0 1 0" />
    <limit effort="1000" lower="-0.65" upper="3.141592654" velocity="6.5"/>
    <dynamics damping="0.7"/>
  </joint>

  <transmission name="tran4">
    <type>transmission_interface/SimpleTransmission</type>
    <joint name="joint4">
      <hardwareInterface>EffortJointInterface</hardwareInterface>
    </joint>
    <actuator name="motor4">
      <hardwareInterface>EffortJointInterface</hardwareInterface>
      <mechanicalReduction>1</mechanicalReduction>
    </actuator>
  </transmission>

  <!-- link 5 -->
  <link name="link5">
    <inertial>
      <origin xyz="-0.029459 0.060231 0.1178" rpy="0 0 0" />
      <mass value="0.35861" />
      <inertia ixx="0.002" ixy="0.0" ixz="0.0" iyy="0.002" iyz="0.0" izz="0.002"/>
    </inertial>
    <visual>
      <origin xyz="0 0 0" rpy="0 0 0" />
      <geometry>
        <mesh filename="package://pro7a_description/meshes/link5.STL" />
      </geometry>
      <material name="">
        <color rgba="0.79216 0.81961 0.93333 1" />
      </material>
    </visual>
    <collision>
      <origin xyz="0 0 0" rpy="0 0 0" />
      <geometry>
        <mesh filename="package://pro7a_description/meshes/link5.STL" />
      </geometry>
    </collision>
  </link>

  <!-- joint 5 -->
  <joint name="joint5" type="revolute">
    <origin xyz="-0.03 0.06 0.195" rpy="0 0 0" />
    <parent link="link5" />
    <child link="link6" />
    <axis xyz="0 0 1" />
    <limit effort="1000" lower="-2.62" upper="2.62" velocity="6.5"/>
    <dynamics damping="0.7"/>
  </joint>

  <transmission name="tran5">
    <type>transmission_interface/SimpleTransmission</type>
    <joint name="joint5">
      <hardwareInterface>EffortJointInterface</hardwareInterface>
    </joint>
    <actuator name="motor5">
      <hardwareInterface>EffortJointInterface</hardwareInterface>
      <mechanicalReduction>1</mechanicalReduction>
    </actuator>
  </transmission>

  <!-- link 6 -->
  <link name="link6">
    <inertial>
      <origin xyz="0 -0.00099225 0.050446" rpy="0 0 0" />
      <mass value="0.2022" />
      <inertia ixx="0.002" ixy="0.0" ixz="0.0" iyy="0.002" iyz="0.0" izz="0.002"/>
    </inertial>
    <visual>
      <origin xyz="0 0 0" rpy="0 0 0" />
      <geometry>
        <mesh filename="package://pro7a_description/meshes/link6.STL" />
      </geometry>
      <material name="">
        <color rgba="1 1 1 1" />
      </material>
    </visual>
    <collision>
      <origin xyz="0 0 0" rpy="0 0 0" />
      <geometry>
        <mesh filename="package://pro7a_description/meshes/link6.STL" />
      </geometry>
    </collision>
  </link>

  <!-- joint 6 -->
  <joint name="joint6" type="revolute">
    <origin xyz="0 -0.048 0.063" rpy="0 0 0" />
    <parent link="link6" />
    <child link="link7" />
    <axis xyz="0 1 0" />
    <limit effort="1000" lower="-1.570796327" upper="1.570796327" velocity="6.5"/>
    <dynamics damping="0.7"/>
  </joint>

  <transmission name="tran6">
    <type>transmission_interface/SimpleTransmission</type>
    <joint name="joint6">
      <hardwareInterface>EffortJointInterface</hardwareInterface>
    </joint>
    <actuator name="motor6">
      <hardwareInterface>EffortJointInterface</hardwareInterface>
      <mechanicalReduction>1</mechanicalReduction>
    </actuator>
  </transmission>

  <!-- link 7 -->
  <link name="link7">
    <inertial>
      <origin xyz="0 0.048354 0.068515" rpy="0 0 0" />
      <mass value="0.16217" />
      <inertia ixx="0.002" ixy="0.0" ixz="0.0" iyy="0.002" iyz="0.0" izz="0.002"/>
    </inertial>
    <visual>
      <origin xyz="0 0 0" rpy="0 0 0" />
      <geometry>
        <mesh filename="package://pro7a_description/meshes/link7.STL" />
      </geometry>
      <material name="">
        <color rgba="0.79216 0.81961 0.93333 1" />
      </material>
    </visual>
    <collision>
      <origin xyz="0 0 0" rpy="0 0 0" />
      <geometry>
        <mesh filename="package://pro7a_description/meshes/link7.STL" />
      </geometry>
    </collision>
  </link>

  <!-- joint 7 -->
  <joint name="joint7" type="revolute">
    <origin xyz="0 0.048 0.123" rpy="0 0 0" />
    <parent link="link7" />
    <child link="end_link" />
    <axis xyz="0 0 1" />
    <limit effort="1000" lower="-2.62" upper="2.62" velocity="6.5"/>
    <dynamics damping="0.7"/>
  </joint>

  <transmission name="tran7">
    <type>transmission_interface/SimpleTransmission</type>
    <joint name="joint7">
      <hardwareInterface>EffortJointInterface</hardwareInterface>
    </joint>
    <actuator name="motor7">
      <hardwareInterface>EffortJointInterface</hardwareInterface>
      <mechanicalReduction>1</mechanicalReduction>
    </actuator>
  </transmission>

  <!-- end link -->
  <link name="end_link">
    <inertial>
      <origin xyz="0 0 0.0031903" rpy="0 0 0" />
      <mass value="0.0062712" />
      <inertia ixx="0.0" ixy="0.0" ixz="0.0" iyy="0.0" iyz="0.0" izz="0.0"/>
    </inertial>
    <visual>
      <origin xyz="0 0 0" rpy="0 0 0" />
      <geometry>
        <mesh filename="package://pro7a_description/meshes/end_link.STL" />
      </geometry>
      <material name="">
        <color rgba="0.79216 0.81961 0.93333 1" />
      </material>
    </visual>
    <collision>
      <origin xyz="0 0 0" rpy="0 0 0" />
      <geometry>
        <mesh filename="package://pro7a_description/meshes/end_link.STL" />
      </geometry>
    </collision>
  </link>

</robot>